Workbook

Sheet README
A1: Hospital Care Analytics Dataset
D2: Sheet | E2: Rows | F2: Description
A3: Dataset purpose | B3: Synthetic health operations dataset for a moderate-to-hard Week 10 final exam using Excel, Access, and Power BI. | D3: Patient_Visits | E3: 1400 | F3: Main transaction table of appointments, admissions, costs, follow-up, satisfaction, and readmission.
A4: Real-life story | B4: A hospital network wants to reduce no-shows, long stays, cost overruns, missed follow-ups, and 30-day readmissions. | D4: Patients | E4: 600 | F4: Patient demographics, area, chronic condition, smoking status, and risk group.
A5: Important note | B5: All patient and doctor names are fictional. This dataset does not contain real patient information. | D5: Doctors | E5: 60 | F5: Doctor lookup table with department, specialization, fee, experience, and capacity.
A6: Suggested student role | B6: Healthcare Data Analyst for hospital management. | D6: Departments | E6: 10 | F6: Hospital department lookup table with budgets and performance targets.
A7: Main analytical question | B7: Which departments, doctors, diagnoses, insurance groups, and patient risk groups are linked with higher cost, longer stays, missed follow-ups, and readmission? | D7: Diagnosis_Guide | E7: 30 | F7: Reference table for diagnosis, disease category, severity, standard cost, expected stay, and department.
A8: Data quality challenges intentionally included | B8: Some inconsistent appointment status labels, inconsistent gender case, area trailing spaces, and limited missing values in doctor, treatment cost, satisfaction, and follow-up fields. | D8: Insurance_Plans | E8: 7 | F8: Insurance lookup table with coverage, claim processing days, and co-pay.

Sheet Patient_Visits
A1: Visit ID | B1: Patient ID | C1: Appointment Date | D1: Appointment Time | E1: Appointment Status | F1: Admission Date | G1: Discharge Date | H1: Department ID | I1: Doctor ID | J1: Diagnosis Code | K1: Visit Type | L1: Admission Source | M1: Treatment Cost | N1: Lab Cost | O1: Medicine Cost | P1: Room Cost | Q1: Total Bill | R1: Insurance Plan ID | S1: Claim Status | T1: Patient Payable | U1: Patient Satisfaction | V1: Follow Up Required | W1: Follow Up Date | X1: Follow Up Completed | Y1: Readmitted Within 30 Days | Z1: Discharge Outcome
A2: V10001 | B2: P2181 | C2: 46071 | D2: 12:45 | E2: Cancelled | H2: D09 | I2: DR152 | J2: DG22 | K2: Outpatient | L2: Doctor Referral | R2: IP06 | S2: Not Applicable | V2: No | X2: Not Required | Z2: Not Treated
A3: V10002 | B3: P2449 | C3: 46032 | D3: 11:00 | E3: Attended | F3: 46032 | G3: 46034 | H3: D09 | I3: DR150 | J3: DG24 | K3: Inpatient | L3: Emergency Walk-in | M3: 7600 | N3: 1350 | O3: 1700 | P3: 5000 | Q3: 17450 | R3: IP01 | S3: Approved | T3: 8150 | U3: 2 | V3: No | X3: Not Required | Y3: Yes | Z3: Improved
A4: V10003 | B4: P2550 | C4: 46082 | D4: 09:00 | E4: Attended | F4: 46082 | G4: 46082 | H4: D04 | I4: DR123 | J4: DG08 | K4: Inpatient | L4: Doctor Referral | M4: 6300 | N4: 900 | O4: 650 | P4: 0 | Q4: 9650 | R4: IP04 | S4: Pending | T4: 3310 | U4: 5 | V4: No | X4: Not Required | Y4: No | Z4: Improved
A5: V10004 | B5: P2226 | C5: 46132 | D5: 13:45 | E5: Attended | F5: 46132 | G5: 46137 | H5: D02 | I5: DR108 | J5: DG02 | K5: Surgery | L5: Scheduled Appointment | M5: 59900 | N5: 6800 | O5: 7050 | P5: 15000 | Q5: 89950 | R5: IP05 | S5: Not Applicable | T5: 89950 | U5: 5 | V5: Yes | W5: 46149 | X5: Yes | Y5: No | Z5: Recovered
A6: V10005 | B6: P2017 | C6: 46024 | D6: 08:15 | E6: Cancelled | H6: D09 | I6: DR149 | J6: DG24 | K6: Inpatient | L6: Emergency Walk-in | R6: IP06 | S6: Not Applicable | V6: No | X6: Not Required | Z6: Not Treated
A7: V10006 | B7: P2488 | C7: 46059 | D7: 12:45 | E7: Attended | F7: 46059 | G7: 46067 | H7: D08 | I7: DR144 | J7: DG21 | K7: Surgery | L7: Scheduled Appointment | M7: 63500 | N7: 8950 | O7: 7200 | P7: 28000 | Q7: 109450 | R7: IP02 | S7: Approved | T7: 39010 | U7: 3 | V7: Yes | W7: 46075 | X7: No | Y7: No | Z7: Stable
A8: V10007 | B8: P2214 | C8: 46051 | D8: 10:45 | E8: Attended | F8: 46051 | G8: 46051 | H8: D05 | I8: DR126 | J8: DG11 | K8: Outpatient | L8: Scheduled Appointment | M8: 20100 | N8: 3250 | O8: 4300 | P8: 0 | Q8: 28450 | R8: IP01 | S8: Approved | T8: 13100 | U8: 4 | V8: No | X8: Not Required | Y8: No | Z8: Recovered
A9: V10008 | B9: P2334 | C9: 46106 | D9: 11:00 | E9: Attended | F9: 46106 | G9: 46106 | H9: D05 | I9: DR130 | J9: DG10 | K9: Outpatient | L9: Scheduled Appointment | M9: 5800 | N9: 750 | O9: 1000 | P9: 0 | Q9: 8350 | R9: IP06 | S9: Approved | T9: 2910 | U9: 5 | V9: No | X9: Not Required | Y9: No | Z9: Improved
A10: V10009 | B10: P2344 | C10: 46168 | D10: 08:30 | E10: Attended | F10: 46168 | G10: 46172 | H10: D03 | I10: DR118 | J10: DG06 | K10: Emergency | L10: Emergency Walk-in | M10: 42600 | N10: 6150 | O10: 8150 | P10: 12000 | Q10: 69900 | R10: IP04 | S10: Approved | T10: 18380 | U10: 3 | V10: Yes | W10: 46185 | X10: No | Y10: No | Z10: Stable
A11: V10010 | B11: P2253 | C11: 46171 | D11: 11:15 | E11: Cancelled | H11: D02 | I11: DR110 | J11: DG03 | K11: Outpatient | L11: Doctor Referral | R11: IP04 | S11: Not Applicable | V11: No | X11: Not Required | Z11: Not Treated
A12: V10011 | B12: P2517 | C12: 46123 | D12: 15:00 | E12: Attended | F12: 46123 | G12: 46123 | H12: D02 | I12: DR111 | J12: DG02 | K12: Outpatient | L12: Scheduled Appointment | M12: 43000 | N12: 5000 | O12: 5850 | P12: 0 | Q12: 55850 | R12: IP07 | S12: Approved | T12: 30920 | V12: Yes | W12: 46132 | X12: No | Y12: No | Z12: Improved
A13: V10012 | B13: P2380 | C13: 46023 | D13: 09:45 | E13: Cancelled | H13: D07 | I13: DR142 | J13: DG16 | K13: Outpatient | L13: Emergency Walk-in | R13: IP03 | S13: Not Applicable | V13: No | X13: Not Required | Z13: Not Treated
A14: V10013 | B14: P2556 | C14: 46043 | D14: 17:30 | E14: Attended | F14: 46043 | G14: 46043 | H14: D08 | I14: DR144 | J14: DG19 | K14: Outpatient | L14: Transfer from Clinic | M14: 27500 | N14: 3200 | O14: 3450 | P14: 0 | Q14: 35950 | R14: IP04 | S14: Approved | T14: 9890 | U14: 5 | V14: No | X14: Not Required | Y14: No | Z14: Recovered
A15: V10014 | B15: P2215 | C15: 46105 | D15: 13:30 | E15: Attended | F15: 46105 | G15: 46107 | H15: D10 | I15: DR156 | J15: DG25 | K15: Inpatient | L15: Doctor Referral | M15: 22000 | N15: 2850 | O15: 3950 | P15: 5000 | Q15: 36300 | R15: IP03 | S15: Approved | T15: 6650 | U15: 5 | V15: No | X15: Not Required | Y15: No | Z15: Stable
A16: V10015 | B16: P2068 | C16: 46045 | D16: 09:45 | E16: Cancelled | H16: D04 | I16: DR122 | J16: DG09 | K16: Surgery | L16: Doctor Referral | R16: IP03 | S16: Not Applicable | V16: No | X16: Not Required | Z16: Not Treated
A17: V10016 | B17: P2115 | C17: 46061 | D17: 11:00 | E17: Attended | F17: 46061 | G17: 46064 | H17: D09 | I17: DR152 | J17: DG22 | K17: Surgery | L17: Emergency Walk-in | M17: 39000 | N17: 3850 | O17: 4050 | P17: 9000 | Q17: 58400 | R17: IP05 | S17: Not Applicable | T17: 58400 | U17: 5 | V17: Yes | W17: 46076 | X17: Yes | Y17: No | Z17: Improved
A18: V10017 | B18: P2581 | C18: 46066 | D18: 12:15 | E18: Attended | F18: 46066 | G18: 46074 | H18: D02 | I18: DR109 | J18: DG02 | K18: Surgery | L18: Scheduled Appointment | M18: 55900 | N18: 5400 | O18: 13350 | P18: 48000 | Q18: 123850 | R18: IP02 | S18: Rejected | T18: 44050 | U18: 3 | V18: No | X18: Not Required | Y18: No | Z18: Recovered
A19: V10018 | B19: P2379 | C19: 46031 | D19: 13:30 | E19: Attended | F19: 46031 | G19: 46033 | H19: D04 | I19: DR123 | J19: DG08 | K19: Inpatient | L19: Transfer from Clinic | M19: 10000 | N19: 1550 | O19: 2400 | P19: 7000 | Q19: 22750 | R19: IP01 | S19: Rejected | T19: 10540 | U19: 4 | V19: No | X19: Not Required | Y19: No | Z19: Recovered
A20: V10019 | B20: P2151 | C20: 46136 | D20: 13:00 | E20: Attended | F20: 46136 | G20: 46144 | H20: D09 | I20: DR154 | J20: DG23 | K20: Emergency | L20: Doctor Referral | M20: 63500 | N20: 6500 | O20: 9750 | P20: 28000 | Q20: 108550 | R20: IP01 | S20: Approved | T20: 49150 | V20: Yes | W20: 46154 | X20: No | Y20: No | Z20: Improved
A21: V10020 | B21: P2525 | C21: 46104 | D21: 17:00 | E21: Cancelled | H21: D03 | I21: DR116 | J21: DG06 | K21: Outpatient | L21: Scheduled Appointment | R21: IP03 | S21: Not Applicable | V21: No | X21: Not Required | Z21: Not Treated
A22: V10021 | B22: P2396 | C22: 46111 | D22: 13:30 | E22: Rescheduled | H22: D06 | I22: DR133 | J22: DG13 | K22: Surgery | L22: Scheduled Appointment | R22: IP04 | S22: Not Applicable | V22: No | X22: Not Required | Z22: Not Treated
A23: V10022 | B23: P2426 | C23: 46064 | D23: 14:45 | E23: Attended | F23: 46064 | G23: 46068 | H23: D09 | I23: DR151 | J23: DG23 | K23: Inpatient | L23: Doctor Referral | M23: 54800 | N23: 9500 | O23: 10350 | P23: 18000 | Q23: 93850 | R23: IP01 | S23: Approved | T23: 42530 | U23: 5 | V23: No | X23: Not Required | Y23: No | Z23: Recovered
A24: V10023 | B24: P2044 | C24: 46172 | D24: 12:45 | E24: Attended | F24: 46172 | G24: 46184 | H24: D10 | I24: DR157 | J24: DG27 | K24: Inpatient | L24: Doctor Referral | M24: 103400 | N24: 16900 | O24: 17650 | P24: 42000 | Q24: 182450 | R24: IP03 | S24: Approved | T24: 28570 | U24: 3 | V24: Yes | W24: 46194 | X24: Yes | Y24: No | Z24: Recovered
A25: V10024 | B25: P2265 | C25: 46053 | D25: 13:00 | E25: No-show | H25: D09 | I25: DR152 | J25: DG22 | K25: Outpatient | L25: Emergency Walk-in | R25: IP06 | S25: Not Applicable | V25: No | X25: Not Required | Z25: Not Treated
A26: V10025 | B26: P2139 | C26: 46092 | D26: 13:45 | E26: Attended | F26: 46092 | G26: 46092 | H26: D04 | I26: DR119 | J26: DG08 | K26: Surgery | L26: Doctor Referral | M26: 7300 | N26: 1150 | O26: 950 | P26: 0 | Q26: 11200 | R26: IP01 | S26: Approved | T26: 5340 | U26: 5 | V26: No | X26: Not Required | Y26: No | Z26: Improved
A27: V10026 | B27: P2148 | C27: 46095 | D27: 13:45 | E27: Attended | F27: 46095 | G27: 46097 | H27: D02 | I27: DR111 | J27: DG01 | K27: Surgery | L27: Doctor Referral | M27: 14800 | N27: 1500 | O27: 1900 | P27: 12000 | Q27: 32200 | R27: IP04 | S27: Pending | T27: 8950 | U27: 5 | V27: No | X27: Not Required | Y27: No | Z27: Stable
A28: V10027 | B28: P2135 | C28: 46112 | D28: 12:30 | E28: Attended | F28: 46112 | G28: 46112 | H28: D01 | I28: DR104 | J28: DG28 | K28: Outpatient | L28: Emergency Walk-in | M28: 33000 | N28: 4950 | O28: 6700 | P28: 0 | Q28: 47150 | R28: IP02 | S28: Approved | T28: 17200 | U28: 4 | V28: No | X28: Not Required | Y28: No | Z28: Stable
A29: V10028 | B29: P2526 | C29: 46053 | D29: 12:00 | E29: Attended | F29: 46053 | G29: 46058 | H29: D08 | I29: DR146 | J29: DG21 | K29: Inpatient | L29: Scheduled Appointment | M29: 42700 | N29: 7250 | O29: 5450 | P29: 17500 | Q29: 74400 | R29: IP01 | S29: Approved | T29: 33780 | U29: 4 | V29: Yes | W29: 46069 | X29: No | Y29: No | Z29: Stable
A30: V10029 | B30: P2593 | C30: 46078 | D30: 11:30 | E30: Attended | F30: 46078 | G30: 46085 | H30: D09 | I30: DR153 | J30: DG22 | K30: Emergency | L30: Doctor Referral | M30: 57700 | N30: 8650 | O30: 7350 | P30: 17500 | Q30: 93200 | R30: IP01 | S30: Approved | T30: 42240 | U30: 3 | V30: Yes | W30: 46095 | X30: Yes | Y30: No | Z30: Recovered
A31: V10030 | B31: P2571 | C31: 46106 | D31: 15:00 | E31: Attended | F31: 46107 | G31: 46112 | H31: D08 | I31: DR143 | J31: DG21 | K31: Inpatient | L31: Scheduled Appointment | M31: 57600 | N31: 9550 | O31: 7400 | P31: 12500 | Q31: 87850 | R31: IP06 | S31: Pending | T31: 26760 | U31: 3 | V31: No | X31: Not Required | Y31: Yes | Z31: Recovered
A32: V10031 | B32: P2405 | C32: 46049 | D32: 10:00 | E32: Attended | F32: 46050 | G32: 46056 | H32: D06 | I32: DR135 | J32: DG13 | K32: Surgery | L32: Scheduled Appointment | M32: 58300 | N32: 8800 | O32: 10900 | P32: 21000 | Q32: 100500 | R32: IP05 | S32: Not Applicable | T32: 100500 | U32: 5 | V32: No | X32: Not Required | Y32: No | Z32: Against Medical Advice
A33: V10032 | B33: P2126 | C33: 46082 | D33: 10:00 | E33: Attended | F33: 46082 | G33: 46083 | H33: D05 | I33: DR128 | J33: DG11 | K33: Outpatient | L33: Doctor Referral | M33: 23400 | N33: 3450 | O33: 2900 | P33: 6000 | Q33: 36750 | R33: IP04 | S33: Approved | T33: 10090 | U33: 5 | V33: No | X33: Not Required | Y33: No | Z33: Recovered
A34: V10033 | B34: P2352 | C34: 46162 | D34: 08:00 | E34: Rescheduled | H34: D09 | I34: DR153 | J34: DG23 | K34: Emergency | L34: Doctor Referral | R34: IP04 | S34: Not Applicable | V34: No | X34: Not Required | Z34: Not Treated
A35: V10034 | B35: P2323 | C35: 46140 | D35: 08:00 | E35: Attended | F35: 46140 | G35: 46142 | H35: D10 | I35: DR158 | J35: DG26 | K35: Inpatient | L35: Scheduled Appointment | M35: 47900 | N35: 6150 | O35: 5600 | P35: 9000 | Q35: 70150 | R35: IP04 | S35: Approved | T35: 18440 | U35: 4 | V35: No | X35: Not Required | Y35: No | Z35: Recovered
A36: V10035 | B36: P2362 | C36: 46105 | D36: 08:00 | E36: Attended | F36: 46105 | G36: 46105 | H36: D09 | I36: DR151 | J36: DG23 | K36: Outpatient | L36: Emergency Walk-in | M36: 49400 | N36: 6050 | O36: 12300 | P36: 0 | Q36: 68950 | R36: IP03 | S36: Approved | T36: 11540 | U36: 4 | V36: Yes | W36: 46115 | X36: Yes | Y36: No | Z36: Recovered
A37: V10036 | B37: P2433 | C37: 46091 | D37: 08:45 | E37: Attended | F37: 46092 | G37: 46096 | H37: D07 | I37: DR140 | J37: DG18 | K37: Surgery | L37: Emergency Walk-in | M37: 41800 | N37: 4200 | O37: 7300 | P37: 14000 | Q37: 68300 | R37: IP01 | S37: Approved | T37: 31030 | U37: 4 | V37: Yes | W37: 46113 | X37: No | Y37: No | Z37: Recovered
A38: V10037 | B38: P2095 | C38: 46047 | D38: 17:30 | E38: Attended | F38: 46048 | G38: 46051 | H38: D10 | I38: DR159 | J38: DG25 | K38: Inpatient | L38: Emergency Walk-in | M38: 20400 | N38: 3250 | O38: 4050 | P38: 10500 | Q38: 40000 | R38: IP03 | S38: Approved | T38: 7200 | U38: 5 | V38: No | X38: Not Required | Y38: No | Z38: Improved
A39: V10038 | B39: P2020 | C39: 46070 | D39: 17:45 | E39: Attended | F39: 46071 | G39: 46076 | H39: D08 | I39: DR147 | J39: DG20 | K39: Surgery | L39: Scheduled Appointment | M39: 90800 | N39: 15500 | O39: 21800 | P39: 12500 | Q39: 142400 | R39: IP03 | S39: Approved | T39: 22560 | U39: 3 | V39: Yes | W39: 46085 | X39: No | Y39: No | Z39: Stable
A40: V10039 | B40: P2274 | C40: 46064 | D40: 12:15 | E40: Attended | F40: 46064 | G40: 46064 | H40: D10 | I40: DR160 | J40: DG27 | K40: Outpatient | L40: Doctor Referral | M40: 83200 | N40: 14900 | O40: 13600 | P40: 0 | Q40: 112700 | R40: IP06 | S40: Approved | T40: 34210 | U40: 5 | V40: Yes | W40: 46071 | X40: Yes | Y40: No | Z40: Stable
...

Sheet Prepared_Visits
A1: Visit ID | B1: Patient ID | C1: Appointment Date | D1: Appointment Time | E1: Appointment Status | F1: Admission Date | G1: Discharge Date | H1: Department ID | I1: Doctor ID | J1: Diagnosis Code | K1: Visit Type | L1: Admission Source | M1: Treatment Cost | N1: Lab Cost | O1: Medicine Cost | P1: Room Cost | Q1: Total Bill | R1: Insurance Plan ID | S1: Claim Status | T1: Patient Payable | U1: Patient Satisfaction | V1: Follow Up Required | W1: Follow Up Date | X1: Follow Up Completed | Y1: Readmitted Within 30 Days | Z1: Discharge Outcome | AA1: DepartmentName | AB1: DiagnosisName | AC1: DiseaseCategory | AD1: InsuranceType | AE1: HospitalServiceFee | AF1: FinalBill | AG1: SatisfactionGroup
A2: V10001 | B2: P2181 | C2: 46071 | D2: 12:45 | E2: Cancelled | H2: D09 | I2: DR152 | J2: DG22 | K2: Outpatient | L2: Doctor Referral | R2: IP06 | S2: Not Applicable | V2: No | X2: Not Required | Z2: Not Treated | AA2: =VLOOKUP(H2,Departments!$A:$B,2,0) -> Pulmonology | AB2: =VLOOKUP(J2,Diagnosis_Guide!$A:$B,2,0) -> Pneumonia | AC2: =VLOOKUP(J2,Diagnosis_Guide!$A:$C,3,0) -> Respiratory | AD2: =VLOOKUP(R2,Insurance_Plans!$A:$C,3,0) -> Public | AE2: =IF(Q2="","",Q2*0.05) | AF2: =IF(Q2="","",Q2+AE2) | AG2: =IF(U2="","Not Available",IF(U2>=4,"High",IF(U2=3,"Medium","Low"))) -> Not Available
A3: V10002 | B3: P2449 | C3: 46032 | D3: 11:00 | E3: Attended | F3: 46032 | G3: 46034 | H3: D09 | I3: DR150 | J3: DG24 | K3: Inpatient | L3: Emergency Walk-in | M3: 7600 | N3: 1350 | O3: 1700 | P3: 5000 | Q3: 17450 | R3: IP01 | S3: Approved | T3: 8150 | U3: 2 | V3: No | X3: Not Required | Y3: Yes | Z3: Improved | AA3: =VLOOKUP(H3,Departments!$A:$B,2,0) -> Pulmonology | AB3: =VLOOKUP(J3,Diagnosis_Guide!$A:$B,2,0) -> Acute Bronchitis | AC3: =VLOOKUP(J3,Diagnosis_Guide!$A:$C,3,0) -> Respiratory | AD3: =VLOOKUP(R3,Insurance_Plans!$A:$C,3,0) -> Public | AE3: =IF(Q3="","",Q3*0.05) -> 872.5 | AF3: =IF(Q3="","",Q3+AE3) -> 18322.5 | AG3: =IF(U3="","Not Available",IF(U3>=4,"High",IF(U3=3,"Medium","Low"))) -> Low
A4: V10003 | B4: P2550 | C4: 46082 | D4: 09:00 | E4: Attended | F4: 46082 | G4: 46082 | H4: D04 | I4: DR123 | J4: DG08 | K4: Inpatient | L4: Doctor Referral | M4: 6300 | N4: 900 | O4: 650 | P4: 0 | Q4: 9650 | R4: IP04 | S4: Pending | T4: 3310 | U4: 5 | V4: No | X4: Not Required | Y4: No | Z4: Improved | AA4: =VLOOKUP(H4,Departments!$A:$B,2,0) -> Orthopedics | AB4: =VLOOKUP(J4,Diagnosis_Guide!$A:$B,2,0) -> Joint Pain | AC4: =VLOOKUP(J4,Diagnosis_Guide!$A:$C,3,0) -> Musculoskeletal | AD4: =VLOOKUP(R4,Insurance_Plans!$A:$C,3,0) -> Employer | AE4: =IF(Q4="","",Q4*0.05) -> 482.5 | AF4: =IF(Q4="","",Q4+AE4) -> 10132.5 | AG4: =IF(U4="","Not Available",IF(U4>=4,"High",IF(U4=3,"Medium","Low"))) -> High
A5: V10004 | B5: P2226 | C5: 46132 | D5: 13:45 | E5: Attended | F5: 46132 | G5: 46137 | H5: D02 | I5: DR108 | J5: DG02 | K5: Surgery | L5: Scheduled Appointment | M5: 59900 | N5: 6800 | O5: 7050 | P5: 15000 | Q5: 89950 | R5: IP05 | S5: Not Applicable | T5: 89950 | U5: 5 | V5: Yes | W5: 46149 | X5: Yes | Y5: No | Z5: Recovered | AA5: =VLOOKUP(H5,Departments!$A:$B,2,0) -> Cardiology | AB5: =VLOOKUP(J5,Diagnosis_Guide!$A:$B,2,0) -> Heart Failure | AC5: =VLOOKUP(J5,Diagnosis_Guide!$A:$C,3,0) -> Cardiovascular | AD5: =VLOOKUP(R5,Insurance_Plans!$A:$C,3,0) -> Self-Pay | AE5: =IF(Q5="","",Q5*0.05) -> 4497.5 | AF5: =IF(Q5="","",Q5+AE5) -> 94447.5 | AG5: =IF(U5="","Not Available",IF(U5>=4,"High",IF(U5=3,"Medium","Low"))) -> High
A6: V10005 | B6: P2017 | C6: 46024 | D6: 08:15 | E6: Cancelled | H6: D09 | I6: DR149 | J6: DG24 | K6: Inpatient | L6: Emergency Walk-in | R6: IP06 | S6: Not Applicable | V6: No | X6: Not Required | Z6: Not Treated | AA6: =VLOOKUP(H6,Departments!$A:$B,2,0) -> Pulmonology | AB6: =VLOOKUP(J6,Diagnosis_Guide!$A:$B,2,0) -> Acute Bronchitis | AC6: =VLOOKUP(J6,Diagnosis_Guide!$A:$C,3,0) -> Respiratory | AD6: =VLOOKUP(R6,Insurance_Plans!$A:$C,3,0) -> Public | AE6: =IF(Q6="","",Q6*0.05) | AF6: =IF(Q6="","",Q6+AE6) | AG6: =IF(U6="","Not Available",IF(U6>=4,"High",IF(U6=3,"Medium","Low"))) -> Not Available
A7: V10006 | B7: P2488 | C7: 46059 | D7: 12:45 | E7: Attended | F7: 46059 | G7: 46067 | H7: D08 | I7: DR144 | J7: DG21 | K7: Surgery | L7: Scheduled Appointment | M7: 63500 | N7: 8950 | O7: 7200 | P7: 28000 | Q7: 109450 | R7: IP02 | S7: Approved | T7: 39010 | U7: 3 | V7: Yes | W7: 46075 | X7: No | Y7: No | Z7: Stable | AA7: =VLOOKUP(H7,Departments!$A:$B,2,0) -> Nephrology | AB7: =VLOOKUP(J7,Diagnosis_Guide!$A:$B,2,0) -> Dialysis Complication | AC7: =VLOOKUP(J7,Diagnosis_Guide!$A:$C,3,0) -> Renal | AD7: =VLOOKUP(R7,Insurance_Plans!$A:$C,3,0) -> Private | AE7: =IF(Q7="","",Q7*0.05) -> 5472.5 | AF7: =IF(Q7="","",Q7+AE7) -> 114922.5 | AG7: =IF(U7="","Not Available",IF(U7>=4,"High",IF(U7=3,"Medium","Low"))) -> Medium
A8: V10007 | B8: P2214 | C8: 46051 | D8: 10:45 | E8: Attended | F8: 46051 | G8: 46051 | H8: D05 | I8: DR126 | J8: DG11 | K8: Outpatient | L8: Scheduled Appointment | M8: 20100 | N8: 3250 | O8: 4300 | P8: 0 | Q8: 28450 | R8: IP01 | S8: Approved | T8: 13100 | U8: 4 | V8: No | X8: Not Required | Y8: No | Z8: Recovered | AA8: =VLOOKUP(H8,Departments!$A:$B,2,0) -> General Medicine | AB8: =VLOOKUP(J8,Diagnosis_Guide!$A:$B,2,0) -> Diabetes Complication | AC8: =VLOOKUP(J8,Diagnosis_Guide!$A:$C,3,0) -> Endocrine/General | AD8: =VLOOKUP(R8,Insurance_Plans!$A:$C,3,0) -> Public | AE8: =IF(Q8="","",Q8*0.05) -> 1422.5 | AF8: =IF(Q8="","",Q8+AE8) -> 29872.5 | AG8: =IF(U8="","Not Available",IF(U8>=4,"High",IF(U8=3,"Medium","Low"))) -> High
A9: V10008 | B9: P2334 | C9: 46106 | D9: 11:00 | E9: Attended | F9: 46106 | G9: 46106 | H9: D05 | I9: DR130 | J9: DG10 | K9: Outpatient | L9: Scheduled Appointment | M9: 5800 | N9: 750 | O9: 1000 | P9: 0 | Q9: 8350 | R9: IP06 | S9: Approved | T9: 2910 | U9: 5 | V9: No | X9: Not Required | Y9: No | Z9: Improved | AA9: =VLOOKUP(H9,Departments!$A:$B,2,0) -> General Medicine | AB9: =VLOOKUP(J9,Diagnosis_Guide!$A:$B,2,0) -> Fever Investigation | AC9: =VLOOKUP(J9,Diagnosis_Guide!$A:$C,3,0) -> Infectious/General | AD9: =VLOOKUP(R9,Insurance_Plans!$A:$C,3,0) -> Public | AE9: =IF(Q9="","",Q9*0.05) -> 417.5 | AF9: =IF(Q9="","",Q9+AE9) -> 8767.5 | AG9: =IF(U9="","Not Available",IF(U9>=4,"High",IF(U9=3,"Medium","Low"))) -> High
A10: V10009 | B10: P2344 | C10: 46168 | D10: 08:30 | E10: Attended | F10: 46168 | G10: 46172 | H10: D03 | I10: DR118 | J10: DG06 | K10: Emergency | L10: Emergency Walk-in | M10: 42600 | N10: 6150 | O10: 8150 | P10: 12000 | Q10: 69900 | R10: IP04 | S10: Approved | T10: 18380 | U10: 3 | V10: Yes | W10: 46185 | X10: No | Y10: No | Z10: Stable | AA10: =VLOOKUP(H10,Departments!$A:$B,2,0) -> Neurology | AB10: =VLOOKUP(J10,Diagnosis_Guide!$A:$B,2,0) -> Seizure Episode | AC10: =VLOOKUP(J10,Diagnosis_Guide!$A:$C,3,0) -> Neurological | AD10: =VLOOKUP(R10,Insurance_Plans!$A:$C,3,0) -> Employer | AE10: =IF(Q10="","",Q10*0.05) -> 3495 | AF10: =IF(Q10="","",Q10+AE10) -> 73395 | AG10: =IF(U10="","Not Available",IF(U10>=4,"High",IF(U10=3,"Medium","Low"))) -> Medium
A11: V10010 | B11: P2253 | C11: 46171 | D11: 11:15 | E11: Cancelled | H11: D02 | I11: DR110 | J11: DG03 | K11: Outpatient | L11: Doctor Referral | R11: IP04 | S11: Not Applicable | V11: No | X11: Not Required | Z11: Not Treated | AA11: =VLOOKUP(H11,Departments!$A:$B,2,0) -> Cardiology | AB11: =VLOOKUP(J11,Diagnosis_Guide!$A:$B,2,0) -> Hypertension Crisis | AC11: =VLOOKUP(J11,Diagnosis_Guide!$A:$C,3,0) -> Cardiovascular | AD11: =VLOOKUP(R11,Insurance_Plans!$A:$C,3,0) -> Employer | AE11: =IF(Q11="","",Q11*0.05) | AF11: =IF(Q11="","",Q11+AE11) | AG11: =IF(U11="","Not Available",IF(U11>=4,"High",IF(U11=3,"Medium","Low"))) -> Not Available
A12: V10011 | B12: P2517 | C12: 46123 | D12: 15:00 | E12: Attended | F12: 46123 | G12: 46123 | H12: D02 | I12: DR111 | J12: DG02 | K12: Outpatient | L12: Scheduled Appointment | M12: 43000 | N12: 5000 | O12: 5850 | P12: 0 | Q12: 55850 | R12: IP07 | S12: Approved | T12: 30920 | V12: Yes | W12: 46132 | X12: No | Y12: No | Z12: Improved | AA12: =VLOOKUP(H12,Departments!$A:$B,2,0) -> Cardiology | AB12: =VLOOKUP(J12,Diagnosis_Guide!$A:$B,2,0) -> Heart Failure | AC12: =VLOOKUP(J12,Diagnosis_Guide!$A:$C,3,0) -> Cardiovascular | AD12: =VLOOKUP(R12,Insurance_Plans!$A:$C,3,0) -> Community | AE12: =IF(Q12="","",Q12*0.05) -> 2792.5 | AF12: =IF(Q12="","",Q12+AE12) -> 58642.5 | AG12: =IF(U12="","Not Available",IF(U12>=4,"High",IF(U12=3,"Medium","Low"))) -> Not Available
A13: V10012 | B13: P2380 | C13: 46023 | D13: 09:45 | E13: Cancelled | H13: D07 | I13: DR142 | J13: DG16 | K13: Outpatient | L13: Emergency Walk-in | R13: IP03 | S13: Not Applicable | V13: No | X13: Not Required | Z13: Not Treated | AA13: =VLOOKUP(H13,Departments!$A:$B,2,0) -> Pediatrics | AB13: =VLOOKUP(J13,Diagnosis_Guide!$A:$B,2,0) -> Pediatric Asthma | AC13: =VLOOKUP(J13,Diagnosis_Guide!$A:$C,3,0) -> Pediatric | AD13: =VLOOKUP(R13,Insurance_Plans!$A:$C,3,0) -> Private | AE13: =IF(Q13="","",Q13*0.05) | AF13: =IF(Q13="","",Q13+AE13) | AG13: =IF(U13="","Not Available",IF(U13>=4,"High",IF(U13=3,"Medium","Low"))) -> Not Available
A14: V10013 | B14: P2556 | C14: 46043 | D14: 17:30 | E14: Attended | F14: 46043 | G14: 46043 | H14: D08 | I14: DR144 | J14: DG19 | K14: Outpatient | L14: Transfer from Clinic | M14: 27500 | N14: 3200 | O14: 3450 | P14: 0 | Q14: 35950 | R14: IP04 | S14: Approved | T14: 9890 | U14: 5 | V14: No | X14: Not Required | Y14: No | Z14: Recovered | AA14: =VLOOKUP(H14,Departments!$A:$B,2,0) -> Nephrology | AB14: =VLOOKUP(J14,Diagnosis_Guide!$A:$B,2,0) -> Kidney Stone | AC14: =VLOOKUP(J14,Diagnosis_Guide!$A:$C,3,0) -> Renal | AD14: =VLOOKUP(R14,Insurance_Plans!$A:$C,3,0) -> Employer | AE14: =IF(Q14="","",Q14*0.05) -> 1797.5 | AF14: =IF(Q14="","",Q14+AE14) -> 37747.5 | AG14: =IF(U14="","Not Available",IF(U14>=4,"High",IF(U14=3,"Medium","Low"))) -> High
A15: V10014 | B15: P2215 | C15: 46105 | D15: 13:30 | E15: Attended | F15: 46105 | G15: 46107 | H15: D10 | I15: DR156 | J15: DG25 | K15: Inpatient | L15: Doctor Referral | M15: 22000 | N15: 2850 | O15: 3950 | P15: 5000 | Q15: 36300 | R15: IP03 | S15: Approved | T15: 6650 | U15: 5 | V15: No | X15: Not Required | Y15: No | Z15: Stable | AA15: =VLOOKUP(H15,Departments!$A:$B,2,0) -> Obstetrics | AB15: =VLOOKUP(J15,Diagnosis_Guide!$A:$B,2,0) -> Antenatal Complication | AC15: =VLOOKUP(J15,Diagnosis_Guide!$A:$C,3,0) -> Maternal Health | AD15: =VLOOKUP(R15,Insurance_Plans!$A:$C,3,0) -> Private | AE15: =IF(Q15="","",Q15*0.05) -> 1815 | AF15: =IF(Q15="","",Q15+AE15) -> 38115 | AG15: =IF(U15="","Not Available",IF(U15>=4,"High",IF(U15=3,"Medium","Low"))) -> High
A16: V10015 | B16: P2068 | C16: 46045 | D16: 09:45 | E16: Cancelled | H16: D04 | I16: DR122 | J16: DG09 | K16: Surgery | L16: Doctor Referral | R16: IP03 | S16: Not Applicable | V16: No | X16: Not Required | Z16: Not Treated | AA16: =VLOOKUP(H16,Departments!$A:$B,2,0) -> Orthopedics | AB16: =VLOOKUP(J16,Diagnosis_Guide!$A:$B,2,0) -> Spinal Injury | AC16: =VLOOKUP(J16,Diagnosis_Guide!$A:$C,3,0) -> Musculoskeletal | AD16: =VLOOKUP(R16,Insurance_Plans!$A:$C,3,0) -> Private | AE16: =IF(Q16="","",Q16*0.05) | AF16: =IF(Q16="","",Q16+AE16) | AG16: =IF(U16="","Not Available",IF(U16>=4,"High",IF(U16=3,"Medium","Low"))) -> Not Available
A17: V10016 | B17: P2115 | C17: 46061 | D17: 11:00 | E17: Attended | F17: 46061 | G17: 46064 | H17: D09 | I17: DR152 | J17: DG22 | K17: Surgery | L17: Emergency Walk-in | M17: 39000 | N17: 3850 | O17: 4050 | P17: 9000 | Q17: 58400 | R17: IP05 | S17: Not Applicable | T17: 58400 | U17: 5 | V17: Yes | W17: 46076 | X17: Yes | Y17: No | Z17: Improved | AA17: =VLOOKUP(H17,Departments!$A:$B,2,0) -> Pulmonology | AB17: =VLOOKUP(J17,Diagnosis_Guide!$A:$B,2,0) -> Pneumonia | AC17: =VLOOKUP(J17,Diagnosis_Guide!$A:$C,3,0) -> Respiratory | AD17: =VLOOKUP(R17,Insurance_Plans!$A:$C,3,0) -> Self-Pay | AE17: =IF(Q17="","",Q17*0.05) -> 2920 | AF17: =IF(Q17="","",Q17+AE17) -> 61320 | AG17: =IF(U17="","Not Available",IF(U17>=4,"High",IF(U17=3,"Medium","Low"))) -> High
A18: V10017 | B18: P2581 | C18: 46066 | D18: 12:15 | E18: Attended | F18: 46066 | G18: 46074 | H18: D02 | I18: DR109 | J18: DG02 | K18: Surgery | L18: Scheduled Appointment | M18: 55900 | N18: 5400 | O18: 13350 | P18: 48000 | Q18: 123850 | R18: IP02 | S18: Rejected | T18: 44050 | U18: 3 | V18: No | X18: Not Required | Y18: No | Z18: Recovered | AA18: =VLOOKUP(H18,Departments!$A:$B,2,0) -> Cardiology | AB18: =VLOOKUP(J18,Diagnosis_Guide!$A:$B,2,0) -> Heart Failure | AC18: =VLOOKUP(J18,Diagnosis_Guide!$A:$C,3,0) -> Cardiovascular | AD18: =VLOOKUP(R18,Insurance_Plans!$A:$C,3,0) -> Private | AE18: =IF(Q18="","",Q18*0.05) -> 6192.5 | AF18: =IF(Q18="","",Q18+AE18) -> 130042.5 | AG18: =IF(U18="","Not Available",IF(U18>=4,"High",IF(U18=3,"Medium","Low"))) -> Medium
A19: V10018 | B19: P2379 | C19: 46031 | D19: 13:30 | E19: Attended | F19: 46031 | G19: 46033 | H19: D04 | I19: DR123 | J19: DG08 | K19: Inpatient | L19: Transfer from Clinic | M19: 10000 | N19: 1550 | O19: 2400 | P19: 7000 | Q19: 22750 | R19: IP01 | S19: Rejected | T19: 10540 | U19: 4 | V19: No | X19: Not Required | Y19: No | Z19: Recovered | AA19: =VLOOKUP(H19,Departments!$A:$B,2,0) -> Orthopedics | AB19: =VLOOKUP(J19,Diagnosis_Guide!$A:$B,2,0) -> Joint Pain | AC19: =VLOOKUP(J19,Diagnosis_Guide!$A:$C,3,0) -> Musculoskeletal | AD19: =VLOOKUP(R19,Insurance_Plans!$A:$C,3,0) -> Public | AE19: =IF(Q19="","",Q19*0.05) -> 1137.5 | AF19: =IF(Q19="","",Q19+AE19) -> 23887.5 | AG19: =IF(U19="","Not Available",IF(U19>=4,"High",IF(U19=3,"Medium","Low"))) -> High
A20: V10019 | B20: P2151 | C20: 46136 | D20: 13:00 | E20: Attended | F20: 46136 | G20: 46144 | H20: D09 | I20: DR154 | J20: DG23 | K20: Emergency | L20: Doctor Referral | M20: 63500 | N20: 6500 | O20: 9750 | P20: 28000 | Q20: 108550 | R20: IP01 | S20: Approved | T20: 49150 | V20: Yes | W20: 46154 | X20: No | Y20: No | Z20: Improved | AA20: =VLOOKUP(H20,Departments!$A:$B,2,0) -> Pulmonology | AB20: =VLOOKUP(J20,Diagnosis_Guide!$A:$B,2,0) -> COPD Exacerbation | AC20: =VLOOKUP(J20,Diagnosis_Guide!$A:$C,3,0) -> Respiratory | AD20: =VLOOKUP(R20,Insurance_Plans!$A:$C,3,0) -> Public | AE20: =IF(Q20="","",Q20*0.05) -> 5427.5 | AF20: =IF(Q20="","",Q20+AE20) -> 113977.5 | AG20: =IF(U20="","Not Available",IF(U20>=4,"High",IF(U20=3,"Medium","Low"))) -> Not Available
A21: V10020 | B21: P2525 | C21: 46104 | D21: 17:00 | E21: Cancelled | H21: D03 | I21: DR116 | J21: DG06 | K21: Outpatient | L21: Scheduled Appointment | R21: IP03 | S21: Not Applicable | V21: No | X21: Not Required | Z21: Not Treated | AA21: =VLOOKUP(H21,Departments!$A:$B,2,0) -> Neurology | AB21: =VLOOKUP(J21,Diagnosis_Guide!$A:$B,2,0) -> Seizure Episode | AC21: =VLOOKUP(J21,Diagnosis_Guide!$A:$C,3,0) -> Neurological | AD21: =VLOOKUP(R21,Insurance_Plans!$A:$C,3,0) -> Private | AE21: =IF(Q21="","",Q21*0.05) | AF21: =IF(Q21="","",Q21+AE21) | AG21: =IF(U21="","Not Available",IF(U21>=4,"High",IF(U21=3,"Medium","Low"))) -> Not Available
A22: V10021 | B22: P2396 | C22: 46111 | D22: 13:30 | E22: Rescheduled | H22: D06 | I22: DR133 | J22: DG13 | K22: Surgery | L22: Scheduled Appointment | R22: IP04 | S22: Not Applicable | V22: No | X22: Not Required | Z22: Not Treated | AA22: =VLOOKUP(H22,Departments!$A:$B,2,0) -> Surgery | AB22: =VLOOKUP(J22,Diagnosis_Guide!$A:$B,2,0) -> Appendicitis Surgery | AC22: =VLOOKUP(J22,Diagnosis_Guide!$A:$C,3,0) -> Surgical | AD22: =VLOOKUP(R22,Insurance_Plans!$A:$C,3,0) -> Employer | AE22: =IF(Q22="","",Q22*0.05) | AF22: =IF(Q22="","",Q22+AE22) | AG22: =IF(U22="","Not Available",IF(U22>=4,"High",IF(U22=3,"Medium","Low"))) -> Not Available
A23: V10022 | B23: P2426 | C23: 46064 | D23: 14:45 | E23: Attended | F23: 46064 | G23: 46068 | H23: D09 | I23: DR151 | J23: DG23 | K23: Inpatient | L23: Doctor Referral | M23: 54800 | N23: 9500 | O23: 10350 | P23: 18000 | Q23: 93850 | R23: IP01 | S23: Approved | T23: 42530 | U23: 5 | V23: No | X23: Not Required | Y23: No | Z23: Recovered | AA23: =VLOOKUP(H23,Departments!$A:$B,2,0) -> Pulmonology | AB23: =VLOOKUP(J23,Diagnosis_Guide!$A:$B,2,0) -> COPD Exacerbation | AC23: =VLOOKUP(J23,Diagnosis_Guide!$A:$C,3,0) -> Respiratory | AD23: =VLOOKUP(R23,Insurance_Plans!$A:$C,3,0) -> Public | AE23: =IF(Q23="","",Q23*0.05) -> 4692.5 | AF23: =IF(Q23="","",Q23+AE23) -> 98542.5 | AG23: =IF(U23="","Not Available",IF(U23>=4,"High",IF(U23=3,"Medium","Low"))) -> High
A24: V10023 | B24: P2044 | C24: 46172 | D24: 12:45 | E24: Attended | F24: 46172 | G24: 46184 | H24: D10 | I24: DR157 | J24: DG27 | K24: Inpatient | L24: Doctor Referral | M24: 103400 | N24: 16900 | O24: 17650 | P24: 42000 | Q24: 182450 | R24: IP03 | S24: Approved | T24: 28570 | U24: 3 | V24: Yes | W24: 46194 | X24: Yes | Y24: No | Z24: Recovered | AA24: =VLOOKUP(H24,Departments!$A:$B,2,0) -> Obstetrics | AB24: =VLOOKUP(J24,Diagnosis_Guide!$A:$B,2,0) -> Emergency C-Section | AC24: =VLOOKUP(J24,Diagnosis_Guide!$A:$C,3,0) -> Maternal Health | AD24: =VLOOKUP(R24,Insurance_Plans!$A:$C,3,0) -> Private | AE24: =IF(Q24="","",Q24*0.05) -> 9122.5 | AF24: =IF(Q24="","",Q24+AE24) -> 191572.5 | AG24: =IF(U24="","Not Available",IF(U24>=4,"High",IF(U24=3,"Medium","Low"))) -> Medium
A25: V10024 | B25: P2265 | C25: 46053 | D25: 13:00 | E25: No-show | H25: D09 | I25: DR152 | J25: DG22 | K25: Outpatient | L25: Emergency Walk-in | R25: IP06 | S25: Not Applicable | V25: No | X25: Not Required | Z25: Not Treated | AA25: =VLOOKUP(H25,Departments!$A:$B,2,0) -> Pulmonology | AB25: =VLOOKUP(J25,Diagnosis_Guide!$A:$B,2,0) -> Pneumonia | AC25: =VLOOKUP(J25,Diagnosis_Guide!$A:$C,3,0) -> Respiratory | AD25: =VLOOKUP(R25,Insurance_Plans!$A:$C,3,0) -> Public | AE25: =IF(Q25="","",Q25*0.05) | AF25: =IF(Q25="","",Q25+AE25) | AG25: =IF(U25="","Not Available",IF(U25>=4,"High",IF(U25=3,"Medium","Low"))) -> Not Available
A26: V10025 | B26: P2139 | C26: 46092 | D26: 13:45 | E26: Attended | F26: 46092 | G26: 46092 | H26: D04 | I26: DR119 | J26: DG08 | K26: Surgery | L26: Doctor Referral | M26: 7300 | N26: 1150 | O26: 950 | P26: 0 | Q26: 11200 | R26: IP01 | S26: Approved | T26: 5340 | U26: 5 | V26: No | X26: Not Required | Y26: No | Z26: Improved | AA26: =VLOOKUP(H26,Departments!$A:$B,2,0) -> Orthopedics | AB26: =VLOOKUP(J26,Diagnosis_Guide!$A:$B,2,0) -> Joint Pain | AC26: =VLOOKUP(J26,Diagnosis_Guide!$A:$C,3,0) -> Musculoskeletal | AD26: =VLOOKUP(R26,Insurance_Plans!$A:$C,3,0) -> Public | AE26: =IF(Q26="","",Q26*0.05) -> 560 | AF26: =IF(Q26="","",Q26+AE26) -> 11760 | AG26: =IF(U26="","Not Available",IF(U26>=4,"High",IF(U26=3,"Medium","Low"))) -> High
A27: V10026 | B27: P2148 | C27: 46095 | D27: 13:45 | E27: Attended | F27: 46095 | G27: 46097 | H27: D02 | I27: DR111 | J27: DG01 | K27: Surgery | L27: Doctor Referral | M27: 14800 | N27: 1500 | O27: 1900 | P27: 12000 | Q27: 32200 | R27: IP04 | S27: Pending | T27: 8950 | U27: 5 | V27: No | X27: Not Required | Y27: No | Z27: Stable | AA27: =VLOOKUP(H27,Departments!$A:$B,2,0) -> Cardiology | AB27: =VLOOKUP(J27,Diagnosis_Guide!$A:$B,2,0) -> Chest Pain | AC27: =VLOOKUP(J27,Diagnosis_Guide!$A:$C,3,0) -> Cardiovascular | AD27: =VLOOKUP(R27,Insurance_Plans!$A:$C,3,0) -> Employer | AE27: =IF(Q27="","",Q27*0.05) -> 1610 | AF27: =IF(Q27="","",Q27+AE27) -> 33810 | AG27: =IF(U27="","Not Available",IF(U27>=4,"High",IF(U27=3,"Medium","Low"))) -> High
A28: V10027 | B28: P2135 | C28: 46112 | D28: 12:30 | E28: Attended | F28: 46112 | G28: 46112 | H28: D01 | I28: DR104 | J28: DG28 | K28: Outpatient | L28: Emergency Walk-in | M28: 33000 | N28: 4950 | O28: 6700 | P28: 0 | Q28: 47150 | R28: IP02 | S28: Approved | T28: 17200 | U28: 4 | V28: No | X28: Not Required | Y28: No | Z28: Stable | AA28: =VLOOKUP(H28,Departments!$A:$B,2,0) -> Emergency | AB28: =VLOOKUP(J28,Diagnosis_Guide!$A:$B,2,0) -> Trauma Observation | AC28: =VLOOKUP(J28,Diagnosis_Guide!$A:$C,3,0) -> Emergency | AD28: =VLOOKUP(R28,Insurance_Plans!$A:$C,3,0) -> Private | AE28: =IF(Q28="","",Q28*0.05) -> 2357.5 | AF28: =IF(Q28="","",Q28+AE28) -> 49507.5 | AG28: =IF(U28="","Not Available",IF(U28>=4,"High",IF(U28=3,"Medium","Low"))) -> High
A29: V10028 | B29: P2526 | C29: 46053 | D29: 12:00 | E29: Attended | F29: 46053 | G29: 46058 | H29: D08 | I29: DR146 | J29: DG21 | K29: Inpatient | L29: Scheduled Appointment | M29: 42700 | N29: 7250 | O29: 5450 | P29: 17500 | Q29: 74400 | R29: IP01 | S29: Approved | T29: 33780 | U29: 4 | V29: Yes | W29: 46069 | X29: No | Y29: No | Z29: Stable | AA29: =VLOOKUP(H29,Departments!$A:$B,2,0) -> Nephrology | AB29: =VLOOKUP(J29,Diagnosis_Guide!$A:$B,2,0) -> Dialysis Complication | AC29: =VLOOKUP(J29,Diagnosis_Guide!$A:$C,3,0) -> Renal | AD29: =VLOOKUP(R29,Insurance_Plans!$A:$C,3,0) -> Public | AE29: =IF(Q29="","",Q29*0.05) -> 3720 | AF29: =IF(Q29="","",Q29+AE29) -> 78120 | AG29: =IF(U29="","Not Available",IF(U29>=4,"High",IF(U29=3,"Medium","Low"))) -> High
A30: V10029 | B30: P2593 | C30: 46078 | D30: 11:30 | E30: Attended | F30: 46078 | G30: 46085 | H30: D09 | I30: DR153 | J30: DG22 | K30: Emergency | L30: Doctor Referral | M30: 57700 | N30: 8650 | O30: 7350 | P30: 17500 | Q30: 93200 | R30: IP01 | S30: Approved | T30: 42240 | U30: 3 | V30: Yes | W30: 46095 | X30: Yes | Y30: No | Z30: Recovered | AA30: =VLOOKUP(H30,Departments!$A:$B,2,0) -> Pulmonology | AB30: =VLOOKUP(J30,Diagnosis_Guide!$A:$B,2,0) -> Pneumonia | AC30: =VLOOKUP(J30,Diagnosis_Guide!$A:$C,3,0) -> Respiratory | AD30: =VLOOKUP(R30,Insurance_Plans!$A:$C,3,0) -> Public | AE30: =IF(Q30="","",Q30*0.05) -> 4660 | AF30: =IF(Q30="","",Q30+AE30) -> 97860 | AG30: =IF(U30="","Not Available",IF(U30>=4,"High",IF(U30=3,"Medium","Low"))) -> Medium
A31: V10030 | B31: P2571 | C31: 46106 | D31: 15:00 | E31: Attended | F31: 46107 | G31: 46112 | H31: D08 | I31: DR143 | J31: DG21 | K31: Inpatient | L31: Scheduled Appointment | M31: 57600 | N31: 9550 | O31: 7400 | P31: 12500 | Q31: 87850 | R31: IP06 | S31: Pending | T31: 26760 | U31: 3 | V31: No | X31: Not Required | Y31: Yes | Z31: Recovered | AA31: =VLOOKUP(H31,Departments!$A:$B,2,0) -> Nephrology | AB31: =VLOOKUP(J31,Diagnosis_Guide!$A:$B,2,0) -> Dialysis Complication | AC31: =VLOOKUP(J31,Diagnosis_Guide!$A:$C,3,0) -> Renal | AD31: =VLOOKUP(R31,Insurance_Plans!$A:$C,3,0) -> Public | AE31: =IF(Q31="","",Q31*0.05) -> 4392.5 | AF31: =IF(Q31="","",Q31+AE31) -> 92242.5 | AG31: =IF(U31="","Not Available",IF(U31>=4,"High",IF(U31=3,"Medium","Low"))) -> Medium
A32: V10031 | B32: P2405 | C32: 46049 | D32: 10:00 | E32: Attended | F32: 46050 | G32: 46056 | H32: D06 | I32: DR135 | J32: DG13 | K32: Surgery | L32: Scheduled Appointment | M32: 58300 | N32: 8800 | O32: 10900 | P32: 21000 | Q32: 100500 | R32: IP05 | S32: Not Applicable | T32: 100500 | U32: 5 | V32: No | X32: Not Required | Y32: No | Z32: Against Medical Advice | AA32: =VLOOKUP(H32,Departments!$A:$B,2,0) -> Surgery | AB32: =VLOOKUP(J32,Diagnosis_Guide!$A:$B,2,0) -> Appendicitis Surgery | AC32: =VLOOKUP(J32,Diagnosis_Guide!$A:$C,3,0) -> Surgical | AD32: =VLOOKUP(R32,Insurance_Plans!$A:$C,3,0) -> Self-Pay | AE32: =IF(Q32="","",Q32*0.05) -> 5025 | AF32: =IF(Q32="","",Q32+AE32) -> 105525 | AG32: =IF(U32="","Not Available",IF(U32>=4,"High",IF(U32=3,"Medium","Low"))) -> High
A33: V10032 | B33: P2126 | C33: 46082 | D33: 10:00 | E33: Attended | F33: 46082 | G33: 46083 | H33: D05 | I33: DR128 | J33: DG11 | K33: Outpatient | L33: Doctor Referral | M33: 23400 | N33: 3450 | O33: 2900 | P33: 6000 | Q33: 36750 | R33: IP04 | S33: Approved | T33: 10090 | U33: 5 | V33: No | X33: Not Required | Y33: No | Z33: Recovered | AA33: =VLOOKUP(H33,Departments!$A:$B,2,0) -> General Medicine | AB33: =VLOOKUP(J33,Diagnosis_Guide!$A:$B,2,0) -> Diabetes Complication | AC33: =VLOOKUP(J33,Diagnosis_Guide!$A:$C,3,0) -> Endocrine/General | AD33: =VLOOKUP(R33,Insurance_Plans!$A:$C,3,0) -> Employer | AE33: =IF(Q33="","",Q33*0.05) -> 1837.5 | AF33: =IF(Q33="","",Q33+AE33) -> 38587.5 | AG33: =IF(U33="","Not Available",IF(U33>=4,"High",IF(U33=3,"Medium","Low"))) -> High
A34: V10033 | B34: P2352 | C34: 46162 | D34: 08:00 | E34: Rescheduled | H34: D09 | I34: DR153 | J34: DG23 | K34: Emergency | L34: Doctor Referral | R34: IP04 | S34: Not Applicable | V34: No | X34: Not Required | Z34: Not Treated | AA34: =VLOOKUP(H34,Departments!$A:$B,2,0) -> Pulmonology | AB34: =VLOOKUP(J34,Diagnosis_Guide!$A:$B,2,0) -> COPD Exacerbation | AC34: =VLOOKUP(J34,Diagnosis_Guide!$A:$C,3,0) -> Respiratory | AD34: =VLOOKUP(R34,Insurance_Plans!$A:$C,3,0) -> Employer | AE34: =IF(Q34="","",Q34*0.05) | AF34: =IF(Q34="","",Q34+AE34) | AG34: =IF(U34="","Not Available",IF(U34>=4,"High",IF(U34=3,"Medium","Low"))) -> Not Available
A35: V10034 | B35: P2323 | C35: 46140 | D35: 08:00 | E35: Attended | F35: 46140 | G35: 46142 | H35: D10 | I35: DR158 | J35: DG26 | K35: Inpatient | L35: Scheduled Appointment | M35: 47900 | N35: 6150 | O35: 5600 | P35: 9000 | Q35: 70150 | R35: IP04 | S35: Approved | T35: 18440 | U35: 4 | V35: No | X35: Not Required | Y35: No | Z35: Recovered | AA35: =VLOOKUP(H35,Departments!$A:$B,2,0) -> Obstetrics | AB35: =VLOOKUP(J35,Diagnosis_Guide!$A:$B,2,0) -> Delivery Care | AC35: =VLOOKUP(J35,Diagnosis_Guide!$A:$C,3,0) -> Maternal Health | AD35: =VLOOKUP(R35,Insurance_Plans!$A:$C,3,0) -> Employer | AE35: =IF(Q35="","",Q35*0.05) -> 3507.5 | AF35: =IF(Q35="","",Q35+AE35) -> 73657.5 | AG35: =IF(U35="","Not Available",IF(U35>=4,"High",IF(U35=3,"Medium","Low"))) -> High
A36: V10035 | B36: P2362 | C36: 46105 | D36: 08:00 | E36: Attended | F36: 46105 | G36: 46105 | H36: D09 | I36: DR151 | J36: DG23 | K36: Outpatient | L36: Emergency Walk-in | M36: 49400 | N36: 6050 | O36: 12300 | P36: 0 | Q36: 68950 | R36: IP03 | S36: Approved | T36: 11540 | U36: 4 | V36: Yes | W36: 46115 | X36: Yes | Y36: No | Z36: Recovered | AA36: =VLOOKUP(H36,Departments!$A:$B,2,0) -> Pulmonology | AB36: =VLOOKUP(J36,Diagnosis_Guide!$A:$B,2,0) -> COPD Exacerbation | AC36: =VLOOKUP(J36,Diagnosis_Guide!$A:$C,3,0) -> Respiratory | AD36: =VLOOKUP(R36,Insurance_Plans!$A:$C,3,0) -> Private | AE36: =IF(Q36="","",Q36*0.05) -> 3447.5 | AF36: =IF(Q36="","",Q36+AE36) -> 72397.5 | AG36: =IF(U36="","Not Available",IF(U36>=4,"High",IF(U36=3,"Medium","Low"))) -> High
A37: V10036 | B37: P2433 | C37: 46091 | D37: 08:45 | E37: Attended | F37: 46092 | G37: 46096 | H37: D07 | I37: DR140 | J37: DG18 | K37: Surgery | L37: Emergency Walk-in | M37: 41800 | N37: 4200 | O37: 7300 | P37: 14000 | Q37: 68300 | R37: IP01 | S37: Approved | T37: 31030 | U37: 4 | V37: Yes | W37: 46113 | X37: No | Y37: No | Z37: Recovered | AA37: =VLOOKUP(H37,Departments!$A:$B,2,0) -> Pediatrics | AB37: =VLOOKUP(J37,Diagnosis_Guide!$A:$B,2,0) -> Neonatal Observation | AC37: =VLOOKUP(J37,Diagnosis_Guide!$A:$C,3,0) -> Pediatric | AD37: =VLOOKUP(R37,Insurance_Plans!$A:$C,3,0) -> Public | AE37: =IF(Q37="","",Q37*0.05) -> 3415 | AF37: =IF(Q37="","",Q37+AE37) -> 71715 | AG37: =IF(U37="","Not Available",IF(U37>=4,"High",IF(U37=3,"Medium","Low"))) -> High
A38: V10037 | B38: P2095 | C38: 46047 | D38: 17:30 | E38: Attended | F38: 46048 | G38: 46051 | H38: D10 | I38: DR159 | J38: DG25 | K38: Inpatient | L38: Emergency Walk-in | M38: 20400 | N38: 3250 | O38: 4050 | P38: 10500 | Q38: 40000 | R38: IP03 | S38: Approved | T38: 7200 | U38: 5 | V38: No | X38: Not Required | Y38: No | Z38: Improved | AA38: =VLOOKUP(H38,Departments!$A:$B,2,0) -> Obstetrics | AB38: =VLOOKUP(J38,Diagnosis_Guide!$A:$B,2,0) -> Antenatal Complication | AC38: =VLOOKUP(J38,Diagnosis_Guide!$A:$C,3,0) -> Maternal Health | AD38: =VLOOKUP(R38,Insurance_Plans!$A:$C,3,0) -> Private | AE38: =IF(Q38="","",Q38*0.05) -> 2000 | AF38: =IF(Q38="","",Q38+AE38) -> 42000 | AG38: =IF(U38="","Not Available",IF(U38>=4,"High",IF(U38=3,"Medium","Low"))) -> High
A39: V10038 | B39: P2020 | C39: 46070 | D39: 17:45 | E39: Attended | F39: 46071 | G39: 46076 | H39: D08 | I39: DR147 | J39: DG20 | K39: Surgery | L39: Scheduled Appointment | M39: 90800 | N39: 15500 | O39: 21800 | P39: 12500 | Q39: 142400 | R39: IP03 | S39: Approved | T39: 22560 | U39: 3 | V39: Yes | W39: 46085 | X39: No | Y39: No | Z39: Stable | AA39: =VLOOKUP(H39,Departments!$A:$B,2,0) -> Nephrology | AB39: =VLOOKUP(J39,Diagnosis_Guide!$A:$B,2,0) -> Chronic Kidney Disease | AC39: =VLOOKUP(J39,Diagnosis_Guide!$A:$C,3,0) -> Renal | AD39: =VLOOKUP(R39,Insurance_Plans!$A:$C,3,0) -> Private | AE39: =IF(Q39="","",Q39*0.05) -> 7120 | AF39: =IF(Q39="","",Q39+AE39) -> 149520 | AG39: =IF(U39="","Not Available",IF(U39>=4,"High",IF(U39=3,"Medium","Low"))) -> Medium
A40: V10039 | B40: P2274 | C40: 46064 | D40: 12:15 | E40: Attended | F40: 46064 | G40: 46064 | H40: D10 | I40: DR160 | J40: DG27 | K40: Outpatient | L40: Doctor Referral | M40: 83200 | N40: 14900 | O40: 13600 | P40: 0 | Q40: 112700 | R40: IP06 | S40: Approved | T40: 34210 | U40: 5 | V40: Yes | W40: 46071 | X40: Yes | Y40: No | Z40: Stable | AA40: =VLOOKUP(H40,Departments!$A:$B,2,0) -> Obstetrics | AB40: =VLOOKUP(J40,Diagnosis_Guide!$A:$B,2,0) -> Emergency C-Section | AC40: =VLOOKUP(J40,Diagnosis_Guide!$A:$C,3,0) -> Maternal Health | AD40: =VLOOKUP(R40,Insurance_Plans!$A:$C,3,0) -> Public | AE40: =IF(Q40="","",Q40*0.05) -> 5635 | AF40: =IF(Q40="","",Q40+AE40) -> 118335 | AG40: =IF(U40="","Not Available",IF(U40>=4,"High",IF(U40=3,"Medium","Low"))) -> High
...

Sheet Patients
A1: Patient ID | B1: Patient Name | C1: Age | D1: Gender | E1: Area | F1: Zone | G1: Blood Type | H1: Chronic Condition | I1: Smoking Status | J1: Risk Group | K1: Registration Date | L1: Emergency Contact Available
A2: P2001 | B2: Mithila Barua | C2: 28 | D2: Female | E2: Savar | F2: Outer Dhaka | G2: AB+ | H2: None | I2: Never | J2: Low | K2: 44488 | L2: Yes
A3: P2002 | B3: Lubna Chowdhury | C3: 80 | D3: Female | E3: Farmgate | F3: Central Dhaka | G3: AB+ | H3: None | I3: Current Smoker | J3: High | K3: 44131 | L3: No
A4: P2003 | B4: Lubna Karim | C4: 73 | D4: Male | E4: Keraniganj | F4: Outer Dhaka | G4: AB+ | H4: Diabetes | I4: Former Smoker | J4: High | K4: 44482 | L4: Yes
A5: P2004 | B5: Mehedi Hasan | C5: 47 | D5: Female | E5: Savar | F5: Outer Dhaka | G5: B- | H5: None | I5: Never | J5: Low | K5: 45351 | L5: Yes
A6: P2005 | B6: Mahmud Barua | C6: 55 | D6: Male | E6: Savar | F6: Outer Dhaka | G6: O- | H6: None | I6: Former Smoker | J6: Medium | K6: 44904 | L6: Yes
A7: P2006 | B7: Sabrina Ahmed | C7: 44 | D7: Female | E7: Uttara | F7: North Dhaka | G7: A- | H7: Asthma | I7: Never | J7: Medium | K7: 45844 | L7: No
A8: P2007 | B8: Farhan Sultana | C8: 28 | D8: Female | E8: Badda | F8: East Dhaka | G8: A+ | H8: Diabetes | I8: Never | J8: Low | K8: 45043 | L8: Yes
A9: P2008 | B9: Tanvir Khan | C9: 33 | D9: Female | E9: Mirpur | F9: North Dhaka | G9: O- | H9: None | I9: Former Smoker | J9: Low | K9: 44273 | L9: Yes
A10: P2009 | B10: Ayesha Islam | C10: 37 | D10: Female | E10: Motijheel | F10: South Dhaka | G10: B- | H10: None | I10: Never | J10: Low | K10: 45114 | L10: Yes
A11: P2010 | B11: Mahmud Barua | C11: 34 | D11: Male | E11: Badda | F11: East Dhaka | G11: A+ | H11: Diabetes | I11: Current Smoker | J11: Medium | K11: 45987 | L11: Yes
A12: P2011 | B12: Hasan Uddin | C12: 38 | D12: Female | E12: Jatrabari | F12: South Dhaka | G12: B+ | H12: Diabetes | I12: Never | J12: Medium | K12: 45277 | L12: Yes
A13: P2012 | B13: Asif Hasan | C13: 55 | D13: Female | E13: Gulshan | F13: North Dhaka | G13: O+ | H13: None | I13: Never | J13: Low | K13: 44838 | L13: Yes
... A601: P2600 | B601: Tareq Jahan | C601: 43 | D601: Female | E601: Wari | F601: South Dhaka | G601: B- | H601: None | I601: Never | J601: Low | K601: 44858 | L601: Yes

Sheet Doctors
A1: Doctor ID | B1: Doctor Name | C1: Department ID | D1: Specialization | E1: Experience Years | F1: Employment Type | G1: Consultation Fee | H1: Weekly Patient Capacity
A2: DR101 | B2: Dr. Imran Karim | C2: D01 | D2: Emergency Medicine | E2: 10 | F2: Full-Time | G2: 1000 | H2: 58
A3: DR102 | B3: Dr. Samira Barua | C3: D01 | D3: Emergency Medicine | E3: 20 | F3: Full-Time | G3: 800 | H3: 56
A4: DR103 | B4: Dr. Farhan Hasan | C4: D01 | D4: Critical Response | E4: 21 | F4: Full-Time | G4: 1000 | H4: 114
A5: DR104 | B5: Dr. Jannat Hasan | C5: D01 | D5: Trauma Care | E5: 20 | F5: Full-Time | G5: 2500 | H5: 45
A6: DR105 | B6: Dr. Asif Chowdhury | C6: D01 | D6: Critical Response | E6: 15 | F6: Full-Time | G6: 1000 | H6: 72
A7: DR106 | B7: Dr. Asif Khan | C7: D01 | D7: Emergency Medicine | E7: 4 | F7: Full-Time | G7: 1200 | H7: 89
A8: DR107 | B8: Dr. Priya Sultana | C8: D02 | D8: Cardiology | E8: 16 | F8: Full-Time | G8: 1500 | H8: 55
A9: DR108 | B9: Dr. Ayesha Jahan | C9: D02 | D9: Heart Failure | E9: 21 | F9: Part-Time | G9: 1200 | H9: 118
A10: DR109 | B10: Dr. Farhan Hossain | C10: D02 | D10: Cardiology | E10: 23 | F10: Full-Time | G10: 1200 | H10: 55
A11: DR110 | B11: Dr. Faria Hasan | C11: D02 | D11: Cardiology | E11: 14 | F11: Full-Time | G11: 2000 | H11: 91
A12: DR111 | B12: Dr. Rakib Das | C12: D02 | D12: Cardiac Imaging | E12: 8 | F12: Full-Time | G12: 2000 | H12: 54
A13: DR112 | B13: Dr. Priya Chowdhury | C13: D02 | D13: Heart Failure | E13: 9 | F13: Full-Time | G13: 1500 | H13: 79
... A61: DR160 | B61: Dr. Mehedi Das | C61: D10 | D61: Gynecology | E61: 19 | F61: Full-Time | G61: 1000 | H61: 50

Sheet Departments
A1: Department ID | B1: Department Name | C1: Floor | D1: Department Head | E1: Monthly Budget | F1: Target Satisfaction Score | G1: Target Readmission Rate | H1: Target Average Stay Days
A2: D01 | B2: Emergency | C2: 1 | D2: Dr. Ayesha Karim | E2: 2500000 | F2: 4.1 | G2: 0.12 | H2: 2
A3: D02 | B3: Cardiology | C3: 5 | D3: Dr. Farhan Ahmed | E3: 3200000 | F3: 4.3 | G3: 0.1 | H3: 4
A4: D03 | B4: Neurology | C4: 6 | D4: Dr. Nadia Rahman | E4: 2800000 | F4: 4.2 | G4: 0.11 | H4: 5
A5: D04 | B5: Orthopedics | C5: 4 | D5: Dr. Saiful Islam | E5: 2100000 | F5: 4 | G5: 0.09 | H5: 3.5
A6: D05 | B6: General Medicine | C6: 3 | D6: Dr. Nusrat Jahan | E6: 1800000 | F6: 4.2 | G6: 0.08 | H6: 2.5
A7: D06 | B7: Surgery | C7: 7 | D7: Dr. Mahmud Hasan | E7: 3600000 | F7: 4.1 | G7: 0.13 | H7: 6
A8: D07 | B8: Pediatrics | C8: 2 | D8: Dr. Sabrina Chowdhury | E8: 1700000 | F8: 4.4 | G8: 0.07 | H8: 2
A9: D08 | B9: Nephrology | C9: 6 | D9: Dr. Tanvir Rahman | E9: 2600000 | F9: 4.1 | G9: 0.14 | H9: 5
A10: D09 | B10: Pulmonology | C10: 5 | D10: Dr. Sharmin Akter | E10: 2300000 | F10: 4 | G10: 0.12 | H10: 4
A11: D10 | B11: Obstetrics | C11: 4 | D11: Dr. Maliha Sultana | E11: 2400000 | F11: 4.3 | G11: 0.06 | H11: 3

Sheet Diagnosis_Guide
A1: Diagnosis Code | B1: Diagnosis Name | C1: Disease Category | D1: Severity Level | E1: Standard Treatment Cost | F1: Expected Stay Days | G1: Criticality Score | H1: Default Department ID
A2: DG01 | B2: Chest Pain | C2: Cardiovascular | D2: Medium | E2: 18000 | F2: 2 | G2: 6 | H2: D02
A3: DG02 | B3: Heart Failure | C3: Cardiovascular | D3: High | E3: 42000 | F3: 5 | G3: 9 | H3: D02
A4: DG03 | B4: Hypertension Crisis | C4: Cardiovascular | D4: High | E4: 30000 | F4: 3 | G4: 8 | H4: D02
A5: DG04 | B5: Stroke Assessment | C5: Neurological | D5: High | E5: 52000 | F5: 6 | G5: 10 | H5: D03
A6: DG05 | B6: Migraine Complication | C6: Neurological | D6: Medium | E6: 16000 | F6: 1 | G6: 5 | H6: D03
A7: DG06 | B7: Seizure Episode | C7: Neurological | D7: High | E7: 31000 | F7: 3 | G7: 8 | H7: D03
A8: DG07 | B8: Fracture Repair | C8: Musculoskeletal | D8: Medium | E8: 35000 | F8: 4 | G8: 7 | H8: D04
A9: DG08 | B9: Joint Pain | C9: Musculoskeletal | D9: Low | E9: 8500 | F9: 1 | G9: 3 | H9: D04
A10: DG09 | B10: Spinal Injury | C10: Musculoskeletal | D10: High | E10: 65000 | F10: 7 | G10: 10 | H10: D04
A11: DG10 | B11: Fever Investigation | C11: Infectious/General | D11: Low | E11: 7000 | F11: 1 | G11: 3 | H11: D05
A12: DG11 | B12: Diabetes Complication | C12: Endocrine/General | D12: Medium | E12: 22000 | F12: 3 | G12: 7 | H12: D05
A13: DG12 | B13: Severe Infection | C13: Infectious/General | D13: High | E13: 45000 | F13: 5 | G13: 9 | H13: D05
... A31: DG30 | B31: Food Poisoning | C31: Emergency | D31: Low | E31: 8000 | F31: 1 | G31: 4 | H31: D01

Sheet Insurance_Plans
A1: Insurance Plan ID | B1: Insurance Provider | C1: Insurance Type | D1: Coverage Percent | E1: Claim Processing Days | F1: Co Pay Amount
A2: IP01 | B2: National Health Support | C2: Public | D2: 0.55 | E2: 12 | F2: 300
A3: IP02 | B3: CarePlus Basic | C3: Private | D3: 0.65 | E3: 8 | F3: 700
A4: IP03 | B4: CarePlus Premium | C4: Private | D4: 0.85 | E4: 5 | F4: 1200
A5: IP04 | B5: Corporate Shield | C5: Employer | D5: 0.75 | E5: 7 | F5: 900
A6: IP05 | B6: Self Pay | C6: Self-Pay | D6: 0 | E6: 0 | F6: 0
A7: IP06 | B7: Senior Care Fund | C7: Public | D7: 0.7 | E7: 10 | F7: 400
A8: IP07 | B8: Micro Health Protect | C8: Community | D8: 0.45 | E8: 15 | F8: 200

Sheet Suggested_KPIs
A1: KPI / Derived Field | B1: Formula Idea | C1: Used For
A2: Actual Length of Stay | B2: Discharge Date - Admission Date | C2: Department efficiency and delay analysis
A3: Stay Variance | B3: Actual Length of Stay - Expected Stay Days | C3: Identify diagnoses causing longer stays
A4: Cost Variance | B4: Total Bill - Standard Treatment Cost | C4: Cost overrun analysis
A5: Cost Variance % | B5: Cost Variance / Standard Treatment Cost | C5: Compare cost overruns fairly
A6: No-Show Flag | B6: Appointment Status is No Show / No-show / Missed | C6: Appointment reliability analysis
A7: Follow-Up Compliance | B7: Follow Up Required = Yes and Follow Up Completed = Yes | C7: Post-discharge care quality
A8: Readmission Rate | B8: Readmitted Within 30 Days = Yes / attended visits | C8: Healthcare outcome quality
A9: Patient Risk Segment | B9: Use Risk Group + Chronic Condition + Age | C9: High-risk patient analysis
